<?xml version="1.0" encoding="UTF-8"?>
<testng-results skipped="0" failed="3" ignored="0" total="3" passed="0">
  <reporter-output>
  </reporter-output>
  <suite name="Default suite" duration-ms="3343" started-at="2018-12-12T07:21:14Z" finished-at="2018-12-12T07:21:18Z">
    <groups>
    </groups>
    <test name="Default test" duration-ms="3343" started-at="2018-12-12T07:21:14Z" finished-at="2018-12-12T07:21:18Z">
      <class name="org.testing.testcase.TC1">
        <test-method status="FAIL" signature="testCase1()[pri:0, instance:org.testing.testcase.TC1@1753acfe]" name="testCase1" duration-ms="2753" started-at="2018-12-12T12:51:15Z" finished-at="2018-12-12T12:51:17Z">
          <exception class="java.lang.ClassCastException">
            <message>
              <![CDATA[java.util.ArrayList cannot be cast to java.lang.String]]>
            </message>
            <full-stacktrace>
              <![CDATA[java.lang.ClassCastException: java.util.ArrayList cannot be cast to java.lang.String
	at org.testing.utilities.ResponseParsing.Response_Content_Compare(ResponseParsing.java:19)
	at org.testing.testSteps.HTTPMethods.GetRequest(HTTPMethods.java:36)
	at org.testing.testcase.TC1.testCase1(TC1.java:19)
	at sun.reflect.NativeMethodAccessorImpl.invoke0(Native Method)
	at sun.reflect.NativeMethodAccessorImpl.invoke(Unknown Source)
	at sun.reflect.DelegatingMethodAccessorImpl.invoke(Unknown Source)
	at java.lang.reflect.Method.invoke(Unknown Source)
	at org.testng.internal.MethodInvocationHelper.invokeMethod(MethodInvocationHelper.java:104)
	at org.testng.internal.Invoker.invokeMethod(Invoker.java:645)
	at org.testng.internal.Invoker.invokeTestMethod(Invoker.java:851)
	at org.testng.internal.Invoker.invokeTestMethods(Invoker.java:1177)
	at org.testng.internal.TestMethodWorker.invokeTestMethods(TestMethodWorker.java:129)
	at org.testng.internal.TestMethodWorker.run(TestMethodWorker.java:112)
	at org.testng.TestRunner.privateRun(TestRunner.java:756)
	at org.testng.TestRunner.run(TestRunner.java:610)
	at org.testng.SuiteRunner.runTest(SuiteRunner.java:387)
	at org.testng.SuiteRunner.runSequentially(SuiteRunner.java:382)
	at org.testng.SuiteRunner.privateRun(SuiteRunner.java:340)
	at org.testng.SuiteRunner.run(SuiteRunner.java:289)
	at org.testng.SuiteRunnerWorker.runSuite(SuiteRunnerWorker.java:52)
	at org.testng.SuiteRunnerWorker.run(SuiteRunnerWorker.java:86)
	at org.testng.TestNG.runSuitesSequentially(TestNG.java:1293)
	at org.testng.TestNG.runSuitesLocally(TestNG.java:1218)
	at org.testng.TestNG.runSuites(TestNG.java:1133)
	at org.testng.TestNG.run(TestNG.java:1104)
	at org.testng.remote.AbstractRemoteTestNG.run(AbstractRemoteTestNG.java:114)
	at org.testng.remote.RemoteTestNG.initAndRun(RemoteTestNG.java:251)
	at org.testng.remote.RemoteTestNG.main(RemoteTestNG.java:77)
]]>
            </full-stacktrace>
          </exception> <!-- java.lang.ClassCastException -->
          <reporter-output>
          </reporter-output>
        </test-method> <!-- testCase1 -->
      </class> <!-- org.testing.testcase.TC1 -->
      <class name="org.testing.testcase.TC2">
        <test-method status="FAIL" signature="testcase2()[pri:0, instance:org.testing.testcase.TC2@2a5ca609]" name="testcase2" duration-ms="499" started-at="2018-12-12T12:51:17Z" finished-at="2018-12-12T12:51:18Z">
          <exception class="java.lang.AssertionError">
            <message>
              <![CDATA[expected [201] but found [500]]]>
            </message>
            <full-stacktrace>
              <![CDATA[java.lang.AssertionError: expected [201] but found [500]
	at org.testng.Assert.fail(Assert.java:94)
	at org.testng.Assert.failNotEquals(Assert.java:513)
	at org.testng.Assert.assertEqualsImpl(Assert.java:135)
	at org.testng.Assert.assertEquals(Assert.java:116)
	at org.testng.Assert.assertEquals(Assert.java:389)
	at org.testng.Assert.assertEquals(Assert.java:399)
	at org.testing.utilities.ResponseValidation.Res_validate(ResponseValidation.java:13)
	at org.testing.testSteps.HTTPMethods.PostRequest(HTTPMethods.java:57)
	at org.testing.testcase.TC2.testcase2(TC2.java:18)
	at sun.reflect.NativeMethodAccessorImpl.invoke0(Native Method)
	at sun.reflect.NativeMethodAccessorImpl.invoke(Unknown Source)
	at sun.reflect.DelegatingMethodAccessorImpl.invoke(Unknown Source)
	at java.lang.reflect.Method.invoke(Unknown Source)
	at org.testng.internal.MethodInvocationHelper.invokeMethod(MethodInvocationHelper.java:104)
	at org.testng.internal.Invoker.invokeMethod(Invoker.java:645)
	at org.testng.internal.Invoker.invokeTestMethod(Invoker.java:851)
	at org.testng.internal.Invoker.invokeTestMethods(Invoker.java:1177)
	at org.testng.internal.TestMethodWorker.invokeTestMethods(TestMethodWorker.java:129)
	at org.testng.internal.TestMethodWorker.run(TestMethodWorker.java:112)
	at org.testng.TestRunner.privateRun(TestRunner.java:756)
	at org.testng.TestRunner.run(TestRunner.java:610)
	at org.testng.SuiteRunner.runTest(SuiteRunner.java:387)
	at org.testng.SuiteRunner.runSequentially(SuiteRunner.java:382)
	at org.testng.SuiteRunner.privateRun(SuiteRunner.java:340)
	at org.testng.SuiteRunner.run(SuiteRunner.java:289)
	at org.testng.SuiteRunnerWorker.runSuite(SuiteRunnerWorker.java:52)
	at org.testng.SuiteRunnerWorker.run(SuiteRunnerWorker.java:86)
	at org.testng.TestNG.runSuitesSequentially(TestNG.java:1293)
	at org.testng.TestNG.runSuitesLocally(TestNG.java:1218)
	at org.testng.TestNG.runSuites(TestNG.java:1133)
	at org.testng.TestNG.run(TestNG.java:1104)
	at org.testng.remote.AbstractRemoteTestNG.run(AbstractRemoteTestNG.java:114)
	at org.testng.remote.RemoteTestNG.initAndRun(RemoteTestNG.java:251)
	at org.testng.remote.RemoteTestNG.main(RemoteTestNG.java:77)
]]>
            </full-stacktrace>
          </exception> <!-- java.lang.AssertionError -->
          <reporter-output>
          </reporter-output>
        </test-method> <!-- testcase2 -->
      </class> <!-- org.testing.testcase.TC2 -->
      <class name="org.testing.testcase.TC3">
        <test-method status="FAIL" signature="testcase1()[pri:0, instance:org.testing.testcase.TC3@20e2cbe0]" name="testcase1" duration-ms="39" started-at="2018-12-12T12:51:18Z" finished-at="2018-12-12T12:51:18Z">
          <exception class="java.lang.AssertionError">
            <message>
              <![CDATA[expected [201] but found [404]]]>
            </message>
            <full-stacktrace>
              <![CDATA[java.lang.AssertionError: expected [201] but found [404]
	at org.testng.Assert.fail(Assert.java:94)
	at org.testng.Assert.failNotEquals(Assert.java:513)
	at org.testng.Assert.assertEqualsImpl(Assert.java:135)
	at org.testng.Assert.assertEquals(Assert.java:116)
	at org.testng.Assert.assertEquals(Assert.java:389)
	at org.testng.Assert.assertEquals(Assert.java:399)
	at org.testing.utilities.ResponseValidation.Res_validate(ResponseValidation.java:13)
	at org.testing.testSteps.HTTPMethods.PostRequest(HTTPMethods.java:57)
	at org.testing.testcase.TC3.testcase1(TC3.java:19)
	at sun.reflect.NativeMethodAccessorImpl.invoke0(Native Method)
	at sun.reflect.NativeMethodAccessorImpl.invoke(Unknown Source)
	at sun.reflect.DelegatingMethodAccessorImpl.invoke(Unknown Source)
	at java.lang.reflect.Method.invoke(Unknown Source)
	at org.testng.internal.MethodInvocationHelper.invokeMethod(MethodInvocationHelper.java:104)
	at org.testng.internal.Invoker.invokeMethod(Invoker.java:645)
	at org.testng.internal.Invoker.invokeTestMethod(Invoker.java:851)
	at org.testng.internal.Invoker.invokeTestMethods(Invoker.java:1177)
	at org.testng.internal.TestMethodWorker.invokeTestMethods(TestMethodWorker.java:129)
	at org.testng.internal.TestMethodWorker.run(TestMethodWorker.java:112)
	at org.testng.TestRunner.privateRun(TestRunner.java:756)
	at org.testng.TestRunner.run(TestRunner.java:610)
	at org.testng.SuiteRunner.runTest(SuiteRunner.java:387)
	at org.testng.SuiteRunner.runSequentially(SuiteRunner.java:382)
	at org.testng.SuiteRunner.privateRun(SuiteRunner.java:340)
	at org.testng.SuiteRunner.run(SuiteRunner.java:289)
	at org.testng.SuiteRunnerWorker.runSuite(SuiteRunnerWorker.java:52)
	at org.testng.SuiteRunnerWorker.run(SuiteRunnerWorker.java:86)
	at org.testng.TestNG.runSuitesSequentially(TestNG.java:1293)
	at org.testng.TestNG.runSuitesLocally(TestNG.java:1218)
	at org.testng.TestNG.runSuites(TestNG.java:1133)
	at org.testng.TestNG.run(TestNG.java:1104)
	at org.testng.remote.AbstractRemoteTestNG.run(AbstractRemoteTestNG.java:114)
	at org.testng.remote.RemoteTestNG.initAndRun(RemoteTestNG.java:251)
	at org.testng.remote.RemoteTestNG.main(RemoteTestNG.java:77)
]]>
            </full-stacktrace>
          </exception> <!-- java.lang.AssertionError -->
          <reporter-output>
          </reporter-output>
        </test-method> <!-- testcase1 -->
      </class> <!-- org.testing.testcase.TC3 -->
    </test> <!-- Default test -->
  </suite> <!-- Default suite -->
</testng-results>
